<?xml version="1.0"?>
<robot name="hyphen" xmlns:xacro="http://ros.org/wiki/xacro">

 <!-- Material Colors -->
 <material name="red">
    <color rgba="1 0 0 1"/>
  </material>

  <material name="green">
    <color rgba="0 1 0 1"/>
  </material>

  <material name="avocado">
    <color rgba="0.1 0.3 0.05 1"/>
  </material>

    <link name="base_link">
        <visual>
            <geometry>
                <box size="0.5 0.5 0.1"/>
            </geometry>
            <material name="avocado" />
        </visual>
    </link>

    <link name="arm_link">
    <visual>
        <geometry>
            <box size="0.1 0.1 0.5"/>
        </geometry>
        <material name="green"/>
    </visual>
</link>

<joint name="arm_joint" type="revolute">
    <parent link="base_link"/>
    <child link="arm_link"/>
    <origin xyz="0 0 0.2" rpy="0 0 0"/>
    <axis xyz="0 1 0"/>
    <limit lower="-3.14" upper="3.14" effort="0.0" velocity="0.0"/>
</joint>

</robot>